<?xml version="1.0"?>
<robot xmlns:xacro="http://www.ros.org/wiki/xacro" name="robot">


    <!-- Define the "world" link -->
    <link name="world"></link>

    <!-- Define the joint connecting the "world" link to the "table_link" -->
    <joint name="table_joint" type="fixed">
        <origin xyz="0.0 0.0 0.0" rpy="0.0 0.0 0.0"/>
        <parent link="world"/>
        <child link="table_link"/>
    </joint>

    <!-- Define the "table_link" -->
    <link name="table_link">  
        <visual>
            <origin xyz="0.0 0.0 0.0273625" rpy="0.0 0.0 0.0"/>
            <geometry>
                <cylinder length="0.054725" radius="0.05080"/>
            </geometry>
            <material name="green">
                <color rgba="0.2 1 0.2 1"/>
            </material>
        </visual>
        <collision>
            <origin xyz="0 0 0.05" rpy="0 0 0"/>
            <geometry>
                <cylinder length="0.054725" radius="0.05080"/>
            </geometry>
        </collision>
    </link>

    <!-- Define the joint connecting the "table_link" to the "base_link" -->
    <joint name="bace_joint" type="revolute">
        <origin xyz="0.0 0.0 0.054725" rpy="0.0 0.0 -1.570796"/>
        <parent link="table_link"/>
        <child link="base_link"/>
        <axis xyz="0.0 0.0 1"/>
        <limit lower="-3.141692" upper="3.141692" effort="60.0" velocity="100.0"/>
    </joint>

    <!-- Define the "base_link" -->
    <link name="base_link">
        <visual>
            <origin xyz="0.0 0.0 0.0931375" rpy="0.0 0.0 0.0"/>
            <geometry>
                <cylinder length="0.186275" radius="0.05080"/>
            </geometry>
            <material name="red">
                <color rgba="1.0 0.0 0.0 1.0"/>
            </material>
        </visual>
        <collision>
            <origin xyz="0.0 0.0 0.0931375" rpy="0.0 0.0 0.0"/>
            <geometry>
                <cylinder length="0.186275" radius="0.05080"/>
            </geometry>
        </collision>
    </link>

    <!-- Define the joint connecting the "base_link" to the "sholder_link" -->
    <joint name="sholder_joint" type="revolute">
        <origin xyz="0.0 0.0 0.186275" rpy="0.0 0.0 0.0"/>
        <parent link="base_link"/>
        <child link="sholder_link"/>
        <axis xyz="0.0 1.0 0.0"/>
        <limit lower="-1.570796" upper="1.570796" effort="60.0" velocity="100.0"/>
    </joint>

    <!-- Define the "sholder_link" -->
    <link name="sholder_link">
        <visual>
            <origin xyz="0.0 0.0 0.2625" rpy="0.0 0.0 0.0"/>
            <geometry>
                <cylinder length="0.525" radius="0.05080"/>
            </geometry>
            <material name="blue">
                <color rgba="0.0 0.0 1.0 1.0"/>
            </material>
        </visual>
        <collision>
            <origin xyz="0.0 0.0 0.2625" rpy="0.0 0.0 0.0"/>
            <geometry>
                <cylinder length="0.525" radius="0.05080"/>
            </geometry>
        </collision>
    </link>

    <joint name="sholder_to_elbow_joint" type="fixed">
        <origin xyz="0.0 0.0 0.525" rpy="-1.570796 0.0 0.0"/>
        <parent link="sholder_link"/>
        <child link="sholder_to_elbow_link"/>
    </joint>

    <link name="sholder_to_elbow_link">
        <visual name="">
            <origin xyz="0.0 0.0 -0.057" rpy="0.0 0.0 0.0"/>
            <geometry>
                <cylinder length="0.114" radius="0.05080"/>
            </geometry>
            <material name="green">
                <color rgba="0.0 1.0 0.0 1.0"/>
            </material>
        </visual>
        <collision>
            <origin xyz="0.0 0.0 -0.057" rpy="0.0 0.0 0.0"/>
            <geometry>
                <cylinder length="0.114" radius="0.05080"/>
            </geometry>
        </collision>
    </link>

    <!-- Define the joint connecting the "sholder_link" to the "elbow_link" -->
    <joint name="elbow_joint" type="revolute">
        <origin xyz="0.0 0.0 -0.114" rpy="-1.570796 0.0 0.0"/>
        <parent link="sholder_to_elbow_link"/>
        <child link="elbow_link"/>
        <axis xyz="0.0 1.0 0.0"/>
        <limit lower="-3.141692" upper="3.141692" effort="60.0" velocity="100.0"/>
    </joint>

    <!-- Define the "elbow_link" -->
    <link name="elbow_link">
        <visual>
            <origin xyz="0.0 0.0 0.105" rpy="0.0 0.0 0.0"/>
            <geometry>
                <cylinder length="0.210" radius="0.05080"/>
            </geometry>
            <material name="green">
                <color rgba="0.0 1.0 0.0 1.0"/>
            </material>
        </visual>
        <collision>
            <origin xyz="0.0 0.0 0.105" rpy="0.0 0.0 0.0"/>
            <geometry>
                <cylinder length="0.210" radius="0.05080"/>
            </geometry>
        </collision>
    </link>

    <!-- Define the joint connecting the "elbow_link" to the "elbow_revolute_link" -->
    <joint name="elbow_revolute_joint" type="revolute">
        <origin xyz="0.0 0.0 0.210" rpy="0.0 0.0 0.0"/>
        <parent link="elbow_link"/>
        <child link="elbow_revolute_link"/>
        <axis xyz="0.0 0.0 -1.0"/>
        <limit lower="-1.570796" upper="1.570796" effort="60.0" velocity="100.0"/>
    </joint>

    <!-- Define the "elbow_revolute_link" -->
    <link name="elbow_revolute_link">
        <visual>
            <origin xyz="0.0 0.0 0.106" rpy="0.0 0.0 0.0"/>
            <geometry>
                <cylinder length="0.212" radius="0.05080"/>
            </geometry>
            <material name="red">
                <color rgba="1.0 0.0 0.0 1.0"/>
            </material>
        </visual>
        <collision>
            <origin xyz="0.0 0.0 0.106" rpy="0.0 0.0 0.0"/>
            <geometry>
                <cylinder length="0.212" radius="0.05080"/>
            </geometry>
        </collision>
    </link>

    <joint name="elbow_revolute_to_wrist_joint" type="fixed">
        <origin xyz="0.0 0.0 0.212" rpy="-1.570796 0.0 0.0"/>
        <parent link="elbow_revolute_link"/>
        <child link="elbow_revolute_to_wrist_link"/>
    </joint>

    <link name="elbow_revolute_to_wrist_link">
        <visual>
            <origin xyz="0.0 0.0 0.05080" rpy="0.0 0.0 0.0"/>
            <geometry>
                <cylinder length="0.110" radius="0.05080"/>
            </geometry>
            <material name="blue">
                <color rgba="0.0 0.0 1.0 1.0"/>
            </material>
        </visual>
        <collision>
            <origin xyz="0.0 0.0 0.05080" rpy="0.0 0.0 0.0"/>
            <geometry>
                <cylinder length="0.110" radius="0.05080"/>
            </geometry>
        </collision>
    </link>

    <!-- Define the joint connecting the "elbow_revolute_link" to the "wrist_link" -->
    <joint name="wrist_joint" type="revolute">
        <origin xyz="0.0 0.0 0.110" rpy="-1.570796 0.0 0.0"/>
        <parent link="elbow_revolute_to_wrist_link"/>
        <child link="wrist_link"/>
        <axis xyz="0.0 -1.0 0.0"/>
        <limit lower="-3.141692" upper="3.141692" effort="60.0" velocity="100.0"/>
    </joint>

    <!-- Define the "wrist_link" -->
    <link name="wrist_link">
        <visual>
            <origin xyz="0.0 0.0 0.095" rpy="0.0 0.0 0.0"/>
            <geometry>
                <cylinder length="0.190" radius="0.05080"/>
            </geometry>
            <material name="green">
                <color rgba="1.0 0.0 0.0 1.0"/>
            </material>
        </visual>
        <collision>
            <origin xyz="0.0 0.0 0.095" rpy="0.0 0.0 0.0"/>
            <geometry>
                <cylinder length="0.190" radius="0.05080"/>
            </geometry>
        </collision>
    </link>

    <!-- Define the joint connecting the "wrist_link" to the "wrist_revolute_link" -->
    <joint name="wrist_revolute_link" type="revolute">
        <origin xyz="0.0 0.0 0.190" rpy="0 0.0 0.0"/>
        <parent link="wrist_link"/>
        <child link="wrist_revolute_link"/>
        <axis xyz="0.0 0.0 1.0"/>
        <limit lower="-3.141692" upper="3.141692" effort="60.0" velocity="100.0"/>
    </joint>

    <!-- Define the "wrist_revolute_link" -->
    <link name="wrist_revolute_link">
        <visual>
            <origin xyz="0.0 0.0 0.025" rpy="0.0 0.0 0.0"/>
            <geometry>
                <cylinder length="0.05" radius="0.05080"/>
            </geometry>
            <material name="red">
                <color rgba="1.0 0.0 0.0 1.0"/>
            </material>
        </visual>
        <collision>
            <origin xyz="0.0 0.0 0.025" rpy="0.0 0.0 0.0"/>
            <geometry>
                <cylinder length="0.05" radius="0.05080"/>
            </geometry>
        </collision>
    </link>
</robot>
